 <robot name="aobo_tuopu"> 
	<link name="link_base">
		<visual>
		  <origin xyz="0. 0. 0." rpy="0. 0. 0." />
		  <geometry>
			<mesh filename="Geometry/A_TABLE_SURPORT.obj" scale="0.001 0.001 0.001" />
		  </geometry>
		  <material
			name="color0">
			<color rgba="0.792156862745098 0.819607843137255 0.933333333333333 0.8" />
		  </material>
		</visual>
		<collision>
          <origin rpy="0 0 0" xyz="0 0 0"/>
          <geometry>
            <mesh filename="Geometry/A_TABLE_SURPORT_vhacd.obj" scale="0.001 0.001 0.001" />
          </geometry>
        </collision>

		<visual>
		  <origin xyz="0. 0. 0." rpy="0. 0. 0." />
		  <geometry>
			<mesh filename="Geometry/BED.obj" scale="0.001 0.001 0.001" />
		  </geometry>
		  <material
			name="color0">
			<color rgba="0.792156862745098 0.819607843137255 0.933333333333333 0.8" />
		  </material>
		</visual>
		<collision>
          <origin rpy="0 0 0" xyz="0 0 0"/>
          <geometry>
            <mesh filename="Geometry/BED_vhacd.obj" scale="0.001 0.001 0.001" />
          </geometry>
        </collision>
    </link>
				
	<link name="link_X_axis">
		<visual>
		  <origin xyz="0. 0. 0." rpy="0. 0. 0." />
		  <geometry>
			<mesh filename="Geometry/X_AXIS.obj" scale="0.001 0.001 0.001" />
		  </geometry>
		  <material
			name="color3">
			<color rgba="0 0 1 0.8" />
		  </material>
		</visual>
		<collision>
          <origin xyz="0. 0. 0." rpy="0. 0. 0." />
          <geometry>
            <mesh filename="Geometry/X_AXIS_vhacd.obj" scale="0.001 0.001 0.001" />
          </geometry>
        </collision>
    </link>
	
	
	<joint name="machine_X" type="prismatic">
        <axis xyz="1 0 0"/>
        <parent link="link_base"/>
        <child link="link_X_axis"/>
        <origin rpy="0. 0. 0." xyz="0. 0. 0."/>
        <limit effort="100" velocity="100"/>
        <joint_properties damping="0.0" friction="0.0"/>
    </joint>
	
	<link name="link_Y_axis">
		<visual>
		  <origin xyz="0. 0. 0." rpy="0. 0. 0." />
		  <geometry>
			<mesh filename="Geometry/Y_Axis.obj" scale="0.001 0.001 0.001" />
		  </geometry>
		  <material
			name="color1">
		  </material>
		</visual>
		<collision>
          <origin xyz="0. 0. 0." rpy="0. 0. 0." />
          <geometry>
            <mesh filename="Geometry/Y_Axis_vhacd.obj" scale="0.001 0.001 0.001" />
          </geometry>
        </collision>
    </link>
	
	<joint name="machine_Y" type="prismatic">
        <axis xyz="0 1 0"/>
        <parent link="link_X_axis"/>
        <child link="link_Y_axis"/>
        <origin rpy="0. 0. 0." xyz="0. 0. 0."/>
        <limit effort="100" velocity="100"/>
        <joint_properties damping="0.0" friction="0.0"/>
    </joint>
	
	<link name="link_Z_axis">
		<visual>
		  <origin xyz="0. 0. 0." rpy="0. 0. 0." />
		  <geometry>
			<mesh filename="Geometry/Z_Axis.obj" scale="0.001 0.001 0.001" />
		  </geometry>
		  <material
			name="color2">
		  </material>
		</visual>
		<collision>
          <origin xyz="0. 0. 0." rpy="0. 0. 0." />
          <geometry>
            <mesh filename="Geometry/Z_Axis_vhacd.obj" scale="0.001 0.001 0.001" />
          </geometry>
        </collision>
    </link>
	
	<joint name="machine_Z" type="prismatic">
        <axis xyz="0 0 1"/>
        <parent link="link_Y_axis"/>
        <child link="link_Z_axis"/>
        <origin rpy="0. 0. 0." xyz="0. 0. 0."/>
        <limit effort="100" velocity="100"/>
        <joint_properties damping="0.0" friction="0.0"/>
    </joint>
	
	<link name="link_A_axis">
		<visual>
		  <origin xyz="0. +0.05 -.128" rpy="0. 0. 0." />
		  <geometry>
			<mesh filename="Geometry/A_TABLE.obj" scale="0.001 0.001 0.001" />
		  </geometry>
		  <material
			name="color1">
			<color rgba="1 0 0 0.8" />
		  </material>
		</visual>
		<collision>
          <origin xyz="0. +0.05 -.128" rpy="0. 0. 0." />
          <geometry>
            <mesh filename="Geometry/A_TABLE_vhacd.obj" scale="0.001 0.001 0.001" />
          </geometry>
        </collision>
    </link>
	
	<joint name="machine_A" type="revolute">
        <axis xyz="1 0 0"/>
        <parent link="link_base"/>
        <child link="link_A_axis"/>
        <origin rpy="0. 0. 0." xyz="0. -.05 .128"/>
        <limit effort="100" velocity="100"/>
        <joint_properties damping="0.0" friction="0.0"/>
    </joint>
    

    <link name="link_C_axis">
		<visual>
		  <origin xyz="0. 0. 0." rpy="0. 0. 0." />
		  <geometry>
			<mesh filename="Geometry/C_TABLE.obj" scale="0.001 0.001 0.001" />
		  </geometry>
		  <material
			name="color2">
			<color rgba="0 1 0 0.8" />
		  </material>
		</visual>
		<collision>
          <origin xyz="0. 0. 0." rpy="0. 0. 0." />
          <geometry>
            <mesh filename="Geometry/C_TABLE_vhacd.obj" scale="0.001 0.001 0.001" />
          </geometry>
        </collision>
        <visual>
		  <origin xyz="-0.2 0. 0." rpy="0. 0. 0." />
		  <geometry>
			<mesh filename="Geometry/i7-(1)-base.obj" scale="0.001 0.001 0.001" />
		  </geometry>
		  <material
			name="robot_orange">
			<color rgba="0.9137255 0.5137254 0. 1" />
		  </material>
		</visual>
		<collision>
          <origin xyz="-0.2 0. 0." rpy="0. 0. 0." />
          <geometry>
            <mesh filename="Geometry/i7-(1)-base_vhacd.obj" scale="0.001 0.001 0.001" />
          </geometry>
        </collision>

		<visual>
		  <origin xyz="0.2 0 0." rpy="0. 0. 0." />
		  <geometry>
			<mesh filename="Geometry/workpiece.obj" scale="0.001 0.001 0.001" />
		  </geometry>
		  <material
			name="robot_orange">
			<color rgba="0.9137255 0.5137254 0. 1" />
		  </material>
		</visual>
		<collision>
          <origin xyz="0.2 0 0." rpy="0. 0. 0." />
          <geometry>
            <mesh filename="Geometry/workpiece_vhacd.obj" scale="0.001 0.001 0.001" />
          </geometry>
        </collision>
    </link>
	
	<joint name="machine_C" type="revolute">
        <axis xyz="0 0 1"/>
        <parent link="link_A_axis"/>
        <child link="link_C_axis"/>
        <origin rpy="0. 0. 0." xyz="0. +.05 -.128"/>
        <limit effort="100" velocity="100"/>
        <joint_properties damping="0.0" friction="0.0"/>
    </joint>
	
	<link name="link_S_axis">
		<visual>
		  <origin xyz="0. 0. 0." rpy="0. 0. 0." />
		  <geometry>
			<mesh filename="Geometry/Spindle.obj" scale="0.001 0.001 0.001" />
		  </geometry>
		  <material
			name="color3">
		  </material>
		</visual>
		<collision>
          <origin xyz="0. 0. 0." rpy="0. 0. 0." />
          <geometry>
            <mesh filename="Geometry/Spindle_vhacd.obj" scale="0.001 0.001 0.001" />
          </geometry>
        </collision>

		<visual>
		  <origin xyz="0. 0. 0.54" rpy="1.57 0. 0." />
		  <geometry>
			<mesh filename="Geometry/cutter_tool.obj" scale="0.001 0.001 0.001" />
		  </geometry>
		  <material
			name="color3">
		  </material>
		</visual>
		<collision>
          <origin xyz="0. 0. 0.54" rpy="1.57 0. 0." />
          <geometry>
            <mesh filename="Geometry/cutter_tool.obj" scale="0.001 0.001 0.001" />
          </geometry>
        </collision>
    </link>
	
	<joint name="machine_S" type="continuous">
        <axis xyz="0 0 1"/>
        <parent link="link_Z_axis"/>
        <child link="link_S_axis"/>
        <origin rpy="0. 0. 0." xyz="0. 0. 0."/>
        <limit effort="100" velocity="100"/>
        <joint_properties damping="0.0" friction="0.0"/>
    </joint>
	
	
	<link name="link_robot_joint1">
		<visual>
		  <origin xyz="0. 0. -.122" rpy="0. 0. 0" />
		  <geometry>
			<mesh filename="Geometry/i7-(2)-ID1.obj" scale="0.001 0.001 0.001" />
		  </geometry>
		  <material
			name="robot_black">
			<color rgba="0.2509804 0.2509804 0.2509804 1" />
		  </material>
		</visual>
		<collision>
          <origin xyz="0. 0. -.122" rpy="0. 0. 0" />
          <geometry>
            <mesh filename="Geometry/i7-(2)-ID1_vhacd.obj" scale="0.001 0.001 0.001" />
          </geometry>
        </collision>
    </link>
	
	<joint name="robot_j1" type="revolute">
        <axis xyz="0 0 1"/>
        <parent link="link_C_axis"/>
        <child link="link_robot_joint1"/>
        <origin rpy="0. 0. 0" xyz="-0.2 0. 0.122"/>
        <limit effort="100" velocity="100"/>
        <joint_properties damping="0.0" friction="0.0"/>
    </joint>
	
	<link name="link_robot_joint2">
		<visual>
		  <origin xyz="0. 0.1215 -.122" rpy="0. 0. 0" />
		  <geometry>
			<mesh filename="Geometry/i7-(3)-ID2.obj" scale="0.001 0.001 0.001" />
		  </geometry>
		  <material
			name="robot_black">
			<color rgba="0.2509804 0.2509804 0.2509804 1" />
		  </material>
		</visual>
		<collision>
          <origin xyz="0. 0.1215 -.122" rpy="0. 0. 0" />
          <geometry>
            <mesh filename="Geometry/i7-(3)-ID2_vhacd.obj" scale="0.001 0.001 0.001" />
          </geometry>
        </collision>
		
		<visual>
		  <origin xyz="0. 0.1215 -0.122" rpy="0. 0. 0" />
		  <geometry>
			<mesh filename="Geometry/i7-(8)-dabiguan.obj" scale="0.001 0.001 0.001" />
		  </geometry>
		  <material
			name="robot_orange">
		  </material>
		</visual>
		<collision>
          <origin xyz="0. 0.1215 -0.122" rpy="0. 0. 0" />
          <geometry>
            <mesh filename="Geometry/i7-(8)-dabiguan_vhacd.obj" scale="0.001 0.001 0.001" />
          </geometry>
        </collision>
		
		<visual>
		  <origin xyz="0. 0.1215 -0.122" rpy="0. 0. 0" />
		  <geometry>
			<mesh filename="Geometry/i7-(4)-ID3.obj" scale="0.001 0.001 0.001" />
		  </geometry>
		  <material name="robot_black"/>
		</visual>
		<collision>
          <origin xyz="0. 0.1215 -0.122" rpy="0. 0. 0" />
          <geometry>
            <mesh filename="Geometry/i7-(4)-ID3_vhacd.obj" scale="0.001 0.001 0.001" />
          </geometry>
        </collision>
    </link>
	
	<joint name="robot_j2" type="revolute">
        <axis xyz="0 1 0"/>
        <parent link="link_robot_joint1"/>
        <child link="link_robot_joint2"/>
        <origin rpy="0. 0. 0." xyz="0. -0.1215 0."/>
        <limit effort="100" velocity="100"/>
        <joint_properties damping="0.0" friction="0.0"/>
    </joint>
	
	<link name="link_robot_joint3">
		<visual>
		  <origin xyz="0. 0.1215 -0.490" rpy="0. 0. 0" />
		  <geometry>
			<mesh filename="Geometry/i7-(10)-wantou.obj" scale="0.001 0.001 0.001" />
		  </geometry>
		  <material
			name="robot_orange">
		  </material>
		</visual>
		<collision>
          <origin xyz="0. 0.1215 -0.490" rpy="0. 0. 0" />
          <geometry>
            <mesh filename="Geometry/i7-(10)-wantou_vhacd.obj" scale="0.001 0.001 0.001" />
          </geometry>
        </collision>
		
		<visual>
		  <origin xyz="0. 0.1215 -0.490" rpy="0. 0. 0" />
		  <geometry>
			<mesh filename="Geometry/i7-(9)-xiaobiguan.obj" scale="0.001 0.001 0.001" />
		  </geometry>
		  <material
			name="robot_orange">
		  </material>
		</visual>
		<collision>
          <origin xyz="0. 0.1215 -0.490" rpy="0. 0. 0" />
          <geometry>
            <mesh filename="Geometry/i7-(9)-xiaobiguan_vhacd.obj" scale="0.001 0.001 0.001" />
          </geometry>
        </collision>
		
		<visual>
		  <origin xyz="0. 0.1215 -0.490" rpy="0. 0. 0" />
		  <geometry>
			<mesh filename="Geometry/i7-(5)-ID4.obj" scale="0.001 0.001 0.001" />
		  </geometry>
		  <material
			name="robot_black">
		  </material>
		</visual>
		<collision>
          <origin xyz="0. 0.1215 -0.490" rpy="0. 0. 0" />
          <geometry>
            <mesh filename="Geometry/i7-(5)-ID4_vhacd.obj" scale="0.001 0.001 0.001" />
          </geometry>
        </collision>
    </link>
	
	<joint name="robot_j3" type="revolute">
        <axis xyz="0 1 0"/>
        <parent link="link_robot_joint2"/>
        <child link="link_robot_joint3"/>
        <origin rpy="0. 0. 0." xyz="0. 0. 0.368"/>
        <limit effort="100" velocity="100"/>
        <joint_properties damping="0.0" friction="0.0"/>
    </joint>
	
	
	<link name="link_robot_joint4">
		<visual>
		  <origin xyz="0. 0.1215 -0.806" rpy="0. 0. 0" />
		  <geometry>
			<mesh filename="Geometry/i7-(6)-ID5.obj" scale="0.001 0.001 0.001" />
		  </geometry>
		  <material
			name="robot_black">
		  </material>
		</visual>
		<collision>
          <origin xyz="0. 0.1215 -0.806" rpy="0. 0. 0" />
          <geometry>
            <mesh filename="Geometry/i7-(6)-ID5_vhacd.obj" scale="0.001 0.001 0.001" />
          </geometry>
        </collision>
    </link>
	
	<joint name="robot_j4" type="revolute">
        <axis xyz="0 1 0"/>
        <parent link="link_robot_joint3"/>
        <child link="link_robot_joint4"/>
        <origin rpy="0 0 0" xyz="0. 0. 0.316"/>
        <limit effort="100" velocity="100"/>
        <joint_properties damping="0.0" friction="0.0"/>
    </joint>
	
	<link name="link_robot_joint5">
		<visual>
		  <origin xyz="0. 0.1215 -0.9085" rpy="0. 0. 0" />
		  <geometry>
			<mesh filename="Geometry/i7-(7)-ID6.obj" scale="0.001 0.001 0.001" />
		  </geometry>
		  <material
			name="robot_black">
		  </material>
		</visual>
		<collision>
          <origin xyz="0. 0.1215 -0.9085" rpy="0. 0. 0" />
          <geometry>
            <mesh filename="Geometry/i7-(7)-ID6_vhacd.obj" scale="0.001 0.001 0.001" />
          </geometry>
        </collision>
    </link>
	
	<joint name="robot_j5" type="revolute">
        <axis xyz="0 0 1"/>
        <parent link="link_robot_joint4"/>
        <child link="link_robot_joint5"/>
        <origin rpy="0 0 0" xyz="0. 0. 0.1025"/>
        <limit effort="100" velocity="100"/>
        <joint_properties damping="0.0" friction="0.0"/>
    </joint>
	
	<link name="link_robot_joint6">
		<visual>
		  <origin xyz="0. 0.2155 -0.9085" rpy="0. 0. 0" />
		  <geometry>
			<mesh filename="Geometry/i7-(11)-endeffect.obj" scale="0.001 0.001 0.001" />
		  </geometry>
		  <material
			name="robot_orange">
		  </material>
		</visual>
		<collision>
          <origin xyz="0. 0.2155 -0.9085" rpy="0. 0. 0" />
          <geometry>
            <mesh filename="Geometry/i7-(11)-endeffect_vhacd.obj" scale="0.001 0.001 0.001" />
          </geometry>
        </collision>
    </link>
	
	<joint name="robot_j6" type="revolute">
        <axis xyz="0 1 0"/>
        <parent link="link_robot_joint5"/>
        <child link="link_robot_joint6"/>
        <origin rpy="0 0 0" xyz="0. -0.094 0."/>
        <limit effort="100" velocity="100"/>
        <joint_properties damping="0.0" friction="0.0"/>
    </joint>

	 <link name="link_robot_end">
		<visual>
		  <origin xyz="0.02 0.034 -0.109" rpy="0. 0. 3.14" />
		  <geometry>
			<mesh filename="Geometry/endeffect_tool.obj" scale="0.001 0.001 0.001" />
		  </geometry>
		  <material
			name="robot_orange">
		  </material>
		</visual>
		<collision>
          <origin xyz="0.02 0.034 -0.109" rpy="0. 0. 3.14" />
          <geometry>
            <mesh filename="Geometry/endeffect_tool.obj" scale="0.001 0.001 0.001" />
          </geometry>
        </collision>
    </link>

	<joint name="robot_end" type="fixed">
        <axis xyz="0 1 0"/>
        <parent link="link_robot_joint6"/>
        <child link="link_robot_end"/>
        <origin rpy="0 0 0" xyz="-0.02 -0.034 0.109"/>
        <limit effort="100" velocity="100"/>
        <joint_properties damping="0.0" friction="0.0"/>
    </joint>

</robot>
