 <robot name="aobo_tuopu"> 
	<link name="base_link">
		<visual>
		  <origin xyz="0. 0. 0." rpy="0. 0. 0." />
		  <geometry>
			<mesh filename="Geometry/A_TABLE_SURPORT.obj" scale="0.001 0.001 0.001" />
		  </geometry>
		  <material
			name="color0">
			<color rgba="0.792156862745098 0.819607843137255 0.933333333333333 0.8" />
		  </material>
		</visual>
		<collision>
          <origin rpy="0 0 0" xyz="0 0 0"/>
          <geometry>
            <mesh filename="Geometry/A_TABLE_SURPORT_vhacd.obj" scale="0.001 0.001 0.001" />
          </geometry>
        </collision>

		<visual>
		  <origin xyz="0. 0. 0." rpy="0. 0. 0." />
		  <geometry>
			<mesh filename="Geometry/BED.obj" scale="0.001 0.001 0.001" />
		  </geometry>
		  <material
			name="color0">
			<color rgba="0.792156862745098 0.819607843137255 0.933333333333333 0.8" />
		  </material>
		</visual>
		<collision>
          <origin rpy="0 0 0" xyz="0 0 0"/>
          <geometry>
            <mesh filename="Geometry/BED_vhacd.obj" scale="0.001 0.001 0.001" />
          </geometry>
        </collision>
    </link>

    <link name="A_axis">
		<visual>
		  <origin xyz="0. +0.05 -.128" rpy="0. 0. 0." />
		  <geometry>
			<mesh filename="Geometry/A_TABLE.obj" scale="0.001 0.001 0.001" />
		  </geometry>
		  <material
			name="color1">
			<color rgba="1 0 0 0.8" />
		  </material>
		</visual>
		<collision>
          <origin xyz="0. +0.05 -.128" rpy="0. 0. 0." />
          <geometry>
            <mesh filename="Geometry/A_TABLE_vhacd.obj" scale="0.001 0.001 0.001" />
          </geometry>
        </collision>
    </link>

    <link name="C_axis">
		<visual>
		  <origin xyz="0. 0. 0." rpy="0. 0. 0." />
		  <geometry>
			<mesh filename="Geometry/C_TABLE.obj" scale="0.001 0.001 0.001" />
		  </geometry>
		  <material
			name="color2">
			<color rgba="0 1 0 0.8" />
		  </material>
		</visual>
		<collision>
          <origin xyz="0. 0. 0." rpy="0. 0. 0." />
          <geometry>
            <mesh filename="Geometry/C_TABLE_vhacd.obj" scale="0.001 0.001 0.001" />
          </geometry>
        </collision>
    </link>

	<link name="X_axis">
		<visual>
		  <origin xyz="0. 0. 0." rpy="0. 0. 0." />
		  <geometry>
			<mesh filename="Geometry/X_AXIS.obj" scale="0.001 0.001 0.001" />
		  </geometry>
		  <material
			name="color3">
			<color rgba="0 0 1 0.8" />
		  </material>
		</visual>
		<collision>
          <origin xyz="0. 0. 0." rpy="0. 0. 0." />
          <geometry>
            <mesh filename="Geometry/X_AXIS_vhacd.obj" scale="0.001 0.001 0.001" />
          </geometry>
        </collision>
    </link>

	<link name="Y_axis">
		<visual>
		  <origin xyz="0. 0. 0." rpy="0. 0. 0." />
		  <geometry>
			<mesh filename="Geometry/Y_Axis.obj" scale="0.001 0.001 0.001" />
		  </geometry>
		  <material
			name="color1">
		  </material>
		</visual>
		<collision>
          <origin xyz="0. 0. 0." rpy="0. 0. 0." />
          <geometry>
            <mesh filename="Geometry/Y_Axis_vhacd.obj" scale="0.001 0.001 0.001" />
          </geometry>
        </collision>
    </link>

	<link name="Z_axis">
		<visual>
		  <origin xyz="0. 0. 0." rpy="0. 0. 0." />
		  <geometry>
			<mesh filename="Geometry/Z_Axis.obj" scale="0.001 0.001 0.001" />
		  </geometry>
		  <material
			name="color2">
		  </material>
		</visual>
		<collision>
          <origin xyz="0. 0. 0." rpy="0. 0. 0." />
          <geometry>
            <mesh filename="Geometry/Z_Axis_vhacd.obj" scale="0.001 0.001 0.001" />
          </geometry>
        </collision>
    </link>

	<link name="S_axis">
		<visual>
		  <origin xyz="0. 0. 0." rpy="0. 0. 0." />
		  <geometry>
			<mesh filename="Geometry/Spindle.obj" scale="0.001 0.001 0.001" />
		  </geometry>
		  <material
			name="color3">
		  </material>
		</visual>
		<collision>
          <origin xyz="0. 0. 0." rpy="0. 0. 0." />
          <geometry>
            <mesh filename="Geometry/Spindle_vhacd.obj" scale="0.001 0.001 0.001" />
          </geometry>
        </collision>
    </link>

	<link name="robot_base_link">
		<visual>
		  <origin xyz="0. 0. 0." rpy="0. 0. 0." />
		  <geometry>
			<mesh filename="Geometry/i7-(1)-base.obj" scale="0.001 0.001 0.001" />
		  </geometry>
		  <material
			name="robot_orange">
			<color rgba="0.9137255 0.5137254 0. 1" />
		  </material>
		</visual>
		<collision>
          <origin xyz="0. 0. 0." rpy="0. 0. 0." />
          <geometry>
            <mesh filename="Geometry/i7-(1)-base_vhacd.obj" scale="0.001 0.001 0.001" />
          </geometry>
        </collision>
    </link>

	<link name="robot_ID1">
		<visual>
		  <origin xyz="0. 0. -.122" rpy="0. 0. 0" />
		  <geometry>
			<mesh filename="Geometry/i7-(2)-ID1.obj" scale="0.001 0.001 0.001" />
		  </geometry>
		  <material
			name="robot_black">
			<color rgba="0.2509804 0.2509804 0.2509804 1" />
		  </material>
		</visual>
		<collision>
          <origin xyz="0. 0. -.122" rpy="0. 0. 0" />
          <geometry>
            <mesh filename="Geometry/i7-(2)-ID1_vhacd.obj" scale="0.001 0.001 0.001" />
          </geometry>
        </collision>
    </link>

	<link name="robot_ID2">
		<visual>
		  <origin xyz="0. 0.1215 -.122" rpy="0. 0. 0" />
		  <geometry>
			<mesh filename="Geometry/i7-(3)-ID2.obj" scale="0.001 0.001 0.001" />
		  </geometry>
		  <material
			name="robot_black">
			<color rgba="0.2509804 0.2509804 0.2509804 1" />
		  </material>
		</visual>
		<collision>
          <origin xyz="0. 0.1215 -.122" rpy="0. 0. 0" />
          <geometry>
            <mesh filename="Geometry/i7-(3)-ID2_vhacd.obj" scale="0.001 0.001 0.001" />
          </geometry>
        </collision>
    </link>

	<link name="robot_dabiguan">
		<visual>
		  <origin xyz="0. 0.1215 -0.122" rpy="0. 0. 0" />
		  <geometry>
			<mesh filename="Geometry/i7-(8)-dabiguan.obj" scale="0.001 0.001 0.001" />
		  </geometry>
		  <material
			name="robot_orange">
		  </material>
		</visual>
		<collision>
          <origin xyz="0. 0.1215 -0.122" rpy="0. 0. 0" />
          <geometry>
            <mesh filename="Geometry/i7-(8)-dabiguan_vhacd.obj" scale="0.001 0.001 0.001" />
          </geometry>
        </collision>
    </link>

	<link name="robot_ID3">
		<visual>
		  <origin xyz="0. 0.1215 -0.122" rpy="0. 0. 0" />
		  <geometry>
			<mesh filename="Geometry/i7-(4)-ID3.obj" scale="0.001 0.001 0.001" />
		  </geometry>
		  <material name="robot_black"/>
		</visual>
		<collision>
          <origin xyz="0. 0.1215 -0.122" rpy="0. 0. 0" />
          <geometry>
            <mesh filename="Geometry/i7-(4)-ID3_vhacd.obj" scale="0.001 0.001 0.001" />
          </geometry>
        </collision>
    </link>

	<link name="robot_wantou">
		<visual>
		  <origin xyz="0. 0.1215 -0.490" rpy="0. 0. 0" />
		  <geometry>
			<mesh filename="Geometry/i7-(10)-wantou.obj" scale="0.001 0.001 0.001" />
		  </geometry>
		  <material
			name="robot_orange">
		  </material>
		</visual>
		<collision>
          <origin xyz="0. 0.1215 -0.490" rpy="0. 0. 0" />
          <geometry>
            <mesh filename="Geometry/i7-(10)-wantou_vhacd.obj" scale="0.001 0.001 0.001" />
          </geometry>
        </collision>
    </link>

	<link name="robot_xiaobiguan">
		<visual>
		  <origin xyz="0. 0.1215 -0.490" rpy="0. 0. 0" />
		  <geometry>
			<mesh filename="Geometry/i7-(9)-xiaobiguan.obj" scale="0.001 0.001 0.001" />
		  </geometry>
		  <material
			name="robot_orange">
		  </material>
		</visual>
		<collision>
          <origin xyz="0. 0.1215 -0.490" rpy="0. 0. 0" />
          <geometry>
            <mesh filename="Geometry/i7-(9)-xiaobiguan_vhacd.obj" scale="0.001 0.001 0.001" />
          </geometry>
        </collision>
    </link>

	<link name="robot_ID4">
		<visual>
		  <origin xyz="0. 0.1215 -0.490" rpy="0. 0. 0" />
		  <geometry>
			<mesh filename="Geometry/i7-(5)-ID4.obj" scale="0.001 0.001 0.001" />
		  </geometry>
		  <material
			name="robot_black">
		  </material>
		</visual>
		<collision>
          <origin xyz="0. 0.1215 -0.490" rpy="0. 0. 0" />
          <geometry>
            <mesh filename="Geometry/i7-(5)-ID4_vhacd.obj" scale="0.001 0.001 0.001" />
          </geometry>
        </collision>
    </link>

	<link name="robot_ID5">
		<visual>
		  <origin xyz="0. 0.1215 -0.806" rpy="0. 0. 0" />
		  <geometry>
			<mesh filename="Geometry/i7-(6)-ID5.obj" scale="0.001 0.001 0.001" />
		  </geometry>
		  <material
			name="robot_black">
		  </material>
		</visual>
		<collision>
          <origin xyz="0. 0.1215 -0.806" rpy="0. 0. 0" />
          <geometry>
            <mesh filename="Geometry/i7-(6)-ID5_vhacd.obj" scale="0.001 0.001 0.001" />
          </geometry>
        </collision>
    </link>

	<link name="robot_ID6">
		<visual>
		  <origin xyz="0. 0.1215 -0.9085" rpy="0. 0. 0" />
		  <geometry>
			<mesh filename="Geometry/i7-(7)-ID6.obj" scale="0.001 0.001 0.001" />
		  </geometry>
		  <material
			name="robot_black">
		  </material>
		</visual>
		<collision>
          <origin xyz="0. 0.1215 -0.9085" rpy="0. 0. 0" />
          <geometry>
            <mesh filename="Geometry/i7-(7)-ID6_vhacd.obj" scale="0.001 0.001 0.001" />
          </geometry>
        </collision>
    </link>

	<link name="robot_end">
		<visual>
		  <origin xyz="0. 0.2155 -0.9085" rpy="0. 0. 0" />
		  <geometry>
			<mesh filename="Geometry/i7-(11)-endeffect.obj" scale="0.001 0.001 0.001" />
		  </geometry>
		  <material
			name="robot_orange">
		  </material>
		</visual>
		<collision>
          <origin xyz="0. 0.2155 -0.9085" rpy="0. 0. 0" />
          <geometry>
            <mesh filename="Geometry/i7-(11)-endeffect_vhacd.obj" scale="0.001 0.001 0.001" />
          </geometry>
        </collision>
    </link>
	
	<joint name="robot_j6" type="revolute">
        <axis xyz="0 1 0"/>
        <parent link="robot_ID6"/>
        <child link="robot_end"/>
        <origin rpy="0 0 0" xyz="0. -0.094 0."/>
        <limit effort="100" velocity="100"/>
        <joint_properties damping="0.0" friction="0.0"/>
    </joint>
	
	<joint name="robot_j5" type="revolute">
        <axis xyz="0 0 1"/>
        <parent link="robot_ID5"/>
        <child link="robot_ID6"/>
        <origin rpy="0 0 0" xyz="0. 0. 0.1025"/>
        <limit effort="100" velocity="100"/>
        <joint_properties damping="0.0" friction="0.0"/>
    </joint>
	
	<joint name="robot_j4" type="revolute">
        <axis xyz="0 1 0"/>
        <parent link="robot_ID4"/>
        <child link="robot_ID5"/>
        <origin rpy="0 0 0" xyz="0. 0. 0.316"/>
        <limit effort="100" velocity="100"/>
        <joint_properties damping="0.0" friction="0.0"/>
    </joint>
	
	<joint name="robot_ID4_xiaobiguan" type="fixed">
        <parent link="robot_xiaobiguan"/>
        <child link="robot_ID4"/>
        <origin rpy="0 0 0" xyz="0. 0. 0."/>
    </joint>
	
	<joint name="robot_wantou_xiaobiguan" type="fixed">
        <parent link="robot_wantou"/>
        <child link="robot_xiaobiguan"/>
        <origin rpy="0. 0. 0." xyz="0. 0. 0."/>
    </joint>
	
	<joint name="robot_j3" type="revolute">
        <axis xyz="0 1 0"/>
        <parent link="robot_ID3"/>
        <child link="robot_wantou"/>
        <origin rpy="0. 0. 0." xyz="0. 0. 0.368"/>
        <limit effort="100" velocity="100"/>
        <joint_properties damping="0.0" friction="0.0"/>
    </joint>
	
	<joint name="robot_ID3_dabiguan" type="fixed">
        <parent link="robot_dabiguan"/>
        <child link="robot_ID3"/>
        <origin rpy="0. 0. 0" xyz="0. 0. 0."/>
    </joint>
	
	<joint name="robot_ID2_dabiguan" type="fixed">
        <parent link="robot_ID2"/>
        <child link="robot_dabiguan"/>
        <origin rpy="0. 0. 0" xyz="0. 0. 0."/>
    </joint>
	
	<joint name="robot_j2" type="revolute">
        <axis xyz="0 1 0"/>
        <parent link="robot_ID1"/>
        <child link="robot_ID2"/>
        <origin rpy="0. 0. 0." xyz="0. -0.1215 0."/>
        <limit effort="100" velocity="100"/>
        <joint_properties damping="0.0" friction="0.0"/>
    </joint>
	
	<joint name="robot_j1" type="revolute">
        <axis xyz="0 0 1"/>
        <parent link="robot_base_link"/>
        <child link="robot_ID1"/>
        <origin rpy="0. 0. 0" xyz="0. 0. 0.122"/>
        <limit effort="100" velocity="100"/>
        <joint_properties damping="0.0" friction="0.0"/>
    </joint>
	
	
	<joint name="robot_base" type="fixed">
        <parent link="C_axis"/>
        <child link="robot_base_link"/>
        <origin rpy="0. 0. 0" xyz="0. 0. 0."/>
    </joint>
	

    <joint name="machine_A" type="revolute">
        <axis xyz="1 0 0"/>
        <parent link="base_link"/>
        <child link="A_axis"/>
        <origin rpy="0. 0. 0." xyz="0. -.05 .128"/>
        <limit effort="100" velocity="100"/>
        <joint_properties damping="0.0" friction="0.0"/>
    </joint>
	
    <joint name="machine_C" type="revolute">
        <axis xyz="0 0 1"/>
        <parent link="A_axis"/>
        <child link="C_axis"/>
        <origin rpy="0. 0. 0." xyz="0. +.05 -.128"/>
        <limit effort="100" velocity="100"/>
        <joint_properties damping="0.0" friction="0.0"/>
    </joint>
	
	<joint name="machine_X" type="prismatic">
        <axis xyz="1 0 0"/>
        <parent link="base_link"/>
        <child link="X_axis"/>
        <origin rpy="0. 0. 0." xyz="0. 0. 0."/>
        <limit effort="100" velocity="100"/>
        <joint_properties damping="0.0" friction="0.0"/>
    </joint>
	
	<joint name="machine_Y" type="prismatic">
        <axis xyz="0 1 0"/>
        <parent link="X_axis"/>
        <child link="Y_axis"/>
        <origin rpy="0. 0. 0." xyz="0. 0. 0."/>
        <limit effort="100" velocity="100"/>
        <joint_properties damping="0.0" friction="0.0"/>
    </joint>
	
	<joint name="machine_Z" type="prismatic">
        <axis xyz="0 0 1"/>
        <parent link="Y_axis"/>
        <child link="Z_axis"/>
        <origin rpy="0. 0. 0." xyz="0. 0. 0."/>
        <limit effort="100" velocity="100"/>
        <joint_properties damping="0.0" friction="0.0"/>
    </joint>
	
	<joint name="machine_S" type="continuous">
        <axis xyz="0 0 1"/>
        <parent link="Z_axis"/>
        <child link="S_axis"/>
        <origin rpy="0. 0. 0." xyz="0. 0. 0."/>
        <limit effort="100" velocity="100"/>
        <joint_properties damping="0.0" friction="0.0"/>
    </joint>
	

</robot>
