 <robot name="aobo_i7">
    <link name="link_base">
        <visual>
		  <origin xyz="0. 0. 0." rpy="0. 0. 0." />
		  <geometry>
			<mesh filename="Geometry/i7-(1)-base.obj" scale="0.001 0.001 0.001" />
		  </geometry>
		  <material
			name="robot_orange">
			<color rgba="0.9137255 0.5137254 0. 1" />
		  </material>
		</visual>
		<collision>
          <origin xyz="0. 0. 0." rpy="0. 0. 0." />
          <geometry>
            <mesh filename="Geometry/i7-(1)-base_vhacd.obj" scale="0.001 0.001 0.001" />
          </geometry>
        </collision>
    </link>

	<link name="link_robot_joint1">
		<visual>
		  <origin xyz="0. 0. -.122" rpy="0. 0. 0" />
		  <geometry>
			<mesh filename="Geometry/i7-(2)-ID1.obj" scale="0.001 0.001 0.001" />
		  </geometry>
		  <material
			name="robot_black">
			<color rgba="0.2509804 0.2509804 0.2509804 1" />
		  </material>
		</visual>
		<collision>
          <origin xyz="0. 0. -.122" rpy="0. 0. 0" />
          <geometry>
            <mesh filename="Geometry/i7-(2)-ID1_vhacd.obj" scale="0.001 0.001 0.001" />
          </geometry>
        </collision>
    </link>

	<joint name="robot_j1" type="revolute">
        <axis xyz="0 0 1"/>
        <parent link="link_base"/>
        <child link="link_robot_joint1"/>
        <origin rpy="0. 0. 0" xyz="0. 0. 0.122"/>
        <limit lower="-3.04" upper="3.04" effort="0" velocity="0" />
    </joint>

	<link name="link_robot_joint2">
		<visual>
		  <origin xyz="0. 0.1215 -.122" rpy="0. 0. 0" />
		  <geometry>
			<mesh filename="Geometry/i7-(3)-ID2.obj" scale="0.001 0.001 0.001" />
		  </geometry>
		  <material
			name="robot_black">
			<color rgba="0.2509804 0.2509804 0.2509804 1" />
		  </material>
		</visual>
		<collision>
          <origin xyz="0. 0.1215 -.122" rpy="0. 0. 0" />
          <geometry>
            <mesh filename="Geometry/i7-(3)-ID2_vhacd.obj" scale="0.001 0.001 0.001" />
          </geometry>
        </collision>

		<visual>
		  <origin xyz="0. 0.1215 -0.122" rpy="0. 0. 0" />
		  <geometry>
			<mesh filename="Geometry/i7-(8)-dabiguan.obj" scale="0.001 0.001 0.001" />
		  </geometry>
		  <material
			name="robot_orange">
		  </material>
		</visual>
		<collision>
          <origin xyz="0. 0.1215 -0.122" rpy="0. 0. 0" />
          <geometry>
            <mesh filename="Geometry/i7-(8)-dabiguan_vhacd.obj" scale="0.001 0.001 0.001" />
          </geometry>
        </collision>

		<visual>
		  <origin xyz="0. 0.1215 -0.122" rpy="0. 0. 0" />
		  <geometry>
			<mesh filename="Geometry/i7-(4)-ID3.obj" scale="0.001 0.001 0.001" />
		  </geometry>
		  <material name="robot_black"/>
		</visual>
		<collision>
          <origin xyz="0. 0.1215 -0.122" rpy="0. 0. 0" />
          <geometry>
            <mesh filename="Geometry/i7-(4)-ID3_vhacd.obj" scale="0.001 0.001 0.001" />
          </geometry>
        </collision>
    </link>

	<joint name="robot_j2" type="revolute">
        <axis xyz="0 1 0"/>
        <parent link="link_robot_joint1"/>
        <child link="link_robot_joint2"/>
        <origin rpy="0. 0. 0." xyz="0. -0.1215 0."/>
        <limit lower="-3.04" upper="3.04" effort="0" velocity="0" />
    </joint>

	<link name="link_robot_joint3">
		<visual>
		  <origin xyz="0. 0.1215 -0.490" rpy="0. 0. 0" />
		  <geometry>
			<mesh filename="Geometry/i7-(10)-wantou.obj" scale="0.001 0.001 0.001" />
		  </geometry>
		  <material
			name="robot_orange">
		  </material>
		</visual>
		<collision>
          <origin xyz="0. 0.1215 -0.490" rpy="0. 0. 0" />
          <geometry>
            <mesh filename="Geometry/i7-(10)-wantou_vhacd.obj" scale="0.001 0.001 0.001" />
          </geometry>
        </collision>

		<visual>
		  <origin xyz="0. 0.1215 -0.490" rpy="0. 0. 0" />
		  <geometry>
			<mesh filename="Geometry/i7-(9)-xiaobiguan.obj" scale="0.001 0.001 0.001" />
		  </geometry>
		  <material
			name="robot_orange">
		  </material>
		</visual>
		<collision>
          <origin xyz="0. 0.1215 -0.490" rpy="0. 0. 0" />
          <geometry>
            <mesh filename="Geometry/i7-(9)-xiaobiguan_vhacd.obj" scale="0.001 0.001 0.001" />
          </geometry>
        </collision>

		<visual>
		  <origin xyz="0. 0.1215 -0.490" rpy="0. 0. 0" />
		  <geometry>
			<mesh filename="Geometry/i7-(5)-ID4.obj" scale="0.001 0.001 0.001" />
		  </geometry>
		  <material
			name="robot_black">
		  </material>
		</visual>
		<collision>
          <origin xyz="0. 0.1215 -0.490" rpy="0. 0. 0" />
          <geometry>
            <mesh filename="Geometry/i7-(5)-ID4_vhacd.obj" scale="0.001 0.001 0.001" />
          </geometry>
        </collision>
    </link>

	<joint name="robot_j3" type="revolute">
        <axis xyz="0 1 0"/>
        <parent link="link_robot_joint2"/>
        <child link="link_robot_joint3"/>
        <origin rpy="0. 0. 0." xyz="0. 0. 0.368"/>
        <limit lower="-3.04" upper="3.04" effort="0" velocity="0" />
    </joint>


	<link name="link_robot_joint4">
		<visual>
		  <origin xyz="0. 0.1215 -0.806" rpy="0. 0. 0" />
		  <geometry>
			<mesh filename="Geometry/i7-(6)-ID5.obj" scale="0.001 0.001 0.001" />
		  </geometry>
		  <material
			name="robot_black">
		  </material>
		</visual>
		<collision>
          <origin xyz="0. 0.1215 -0.806" rpy="0. 0. 0" />
          <geometry>
            <mesh filename="Geometry/i7-(6)-ID5_vhacd.obj" scale="0.001 0.001 0.001" />
          </geometry>
        </collision>
    </link>

	<joint name="robot_j4" type="revolute">
        <axis xyz="0 1 0"/>
        <parent link="link_robot_joint3"/>
        <child link="link_robot_joint4"/>
        <origin rpy="0 0 0" xyz="0. 0. 0.316"/>
        <limit lower="-3.04" upper="3.04" effort="0" velocity="0" />
    </joint>

	<link name="link_robot_joint5">
		<visual>
		  <origin xyz="0. 0.1215 -0.9085" rpy="0. 0. 0" />
		  <geometry>
			<mesh filename="Geometry/i7-(7)-ID6.obj" scale="0.001 0.001 0.001" />
		  </geometry>
		  <material
			name="robot_black">
		  </material>
		</visual>
		<collision>
          <origin xyz="0. 0.1215 -0.9085" rpy="0. 0. 0" />
          <geometry>
            <mesh filename="Geometry/i7-(7)-ID6_vhacd.obj" scale="0.001 0.001 0.001" />
          </geometry>
        </collision>
    </link>

	<joint name="robot_j5" type="revolute">
        <axis xyz="0 0 1"/>
        <parent link="link_robot_joint4"/>
        <child link="link_robot_joint5"/>
        <origin rpy="0 0 0" xyz="0. 0. 0.1025"/>
        <limit lower="-3.04" upper="3.04" effort="0" velocity="0" />
    </joint>

	<link name="link_robot_joint6">
		<visual>
		  <origin xyz="0. 0.2155 -0.9085" rpy="0. 0. 0" />
		  <geometry>
			<mesh filename="Geometry/i7-(11)-endeffect.obj" scale="0.001 0.001 0.001" />
		  </geometry>
		  <material
			name="robot_orange">
		  </material>
		</visual>
		<collision>
          <origin xyz="0. 0.2155 -0.9085" rpy="0. 0. 0" />
          <geometry>
            <mesh filename="Geometry/i7-(11)-endeffect_vhacd.obj" scale="0.001 0.001 0.001" />
          </geometry>
        </collision>
    </link>

	<joint name="robot_j6" type="revolute">
        <axis xyz="0 1 0"/>
        <parent link="link_robot_joint5"/>
        <child link="link_robot_joint6"/>
        <origin rpy="0 0 0" xyz="0. -0.094 0."/>
        <limit lower="-3.04" upper="3.04" effort="0" velocity="0" />
    </joint>

	 <link name="link_robot_end">
		<visual>
		  <origin xyz="0 0 0" rpy="1.57 0 -1.57" />
		  <geometry>
			<mesh filename="Geometry/endeffect_tool.obj" scale="0.001 0.001 0.001" />
		  </geometry>
		  <material
			name="robot_orange">
		  </material>
		</visual>
		<collision>
          <origin xyz="0 0 0" rpy="1.57 0 -1.57" />
          <geometry>
            <mesh filename="Geometry/endeffect_tool.obj" scale="0.001 0.001 0.001" />
          </geometry>
        </collision>
    </link>

	<joint name="robot_end" type="fixed">
		<axis xyz="0 1 0"/>
        <parent link="link_robot_joint6"/>
        <child link="link_robot_end"/>
        <origin rpy="0 0 0" xyz="-0.02 -0.034 0.109"/>
    </joint>

</robot>
